Workbook

Sheet Summary
A1: The Clothing Cove — Filter & Search Readiness Plan
A2: Audit date: June 10, 2026 | theclothingcove.com | Goal: make the catalog searchable by color, size, type, brand & material | Scope: in-stock products
A4: FILTERS LIVE TODAY | D4: APPAREL MISSING SIZE | G4: PRODUCTS MISSING COLOR | J4: COLOR SWATCH-READY
A5: 2 of 6 | D5: 152 | G5: 4194 | J5: 0.10271102
A6: Availability and Price only | D6: in-stock apparel & footwear without a Size option | G6: in-stock products that carry colors but have no Color option | J6: 1,201 products mapped to the palette metafield
A8: OBJECTIVE
A9: Make the in-stock catalog searchable by the filters shoppers expect — color, size, garment type, brand and material. Each filter requires its product metadata to exist, be standardized, and be enabled in the storefront. The plan below brings each filter to that state, in priority order.
A12: FILTER READINESS AT A GLANCE (see ‘Filter Readiness Map’ for the full plan)
A13: Target filter | B13: Products ready | C13: In scope | D13: Data readiness
A14: Availability | B14: 11693 | C14: 11693 | D14: =IF(C14=0,0,B14/C14) -> 1
A15: Price | B15: 11693 | C15: 11693 | D15: =IF(C15=0,0,B15/C15) -> 1
A16: Brand | B16: 11693 | C16: 11693 | D16: =IF(C16=0,0,B16/C16) -> 1
A17: Garment type | B17: 11642 | C17: 11693 | D17: =IF(C17=0,0,B17/C17) -> 0.99563842
A18: Color (option) | B18: 4891 | C18: 9085 | D18: =IF(C18=0,0,B18/C18) -> 0.53835993
A19: Size (option) | B19: 2757 | C19: 2909 | D19: =IF(C19=0,0,B19/C19) -> 0.94774837
A20: Color swatches | B20: 1201 | C20: 11693 | D20: =IF(C20=0,0,B20/C20) -> 0.10271102
A21: Material / fabric | B21: 0 | C21: 11693 | D21: =IF(C21=0,0,B21/C21) -> 0
A29: ATTRIBUTE GAPS BY PRIORITY (in-stock products to update)
A30: Attribute gap (priority order) | C30: Products
A31: 1 — Apparel & footwear missing a Size option | C31: =COUNTIF('Problem Worklist'!$A:$A,1) -> 95
A32: 2 — Apparel missing a Color option | C32: =COUNTIF('Problem Worklist'!$A:$A,2) -> 161
A33: 3 — Accessories missing a Color option | C33: =COUNTIF('Problem Worklist'!$A:$A,3) -> 1049
A34: 4 — Jewelry missing a Color option | C34: =COUNTIF('Problem Worklist'!$A:$A,4) -> 2999
A35: Total products to update | C35: =SUM(C31:C34) -> 4304
A37: CATALOG OVERVIEW
A38: Status | B38: Products | C38: % of active
A39: In stock | B39: 11693 | C39: =B39/$B$41 -> 0.32438206
A40: Out of stock (still published) | B40: 24354 | C40: =B40/$B$41 -> 0.67561794
A41: Active products (total) | B41: 36047 | C41: =B41/$B$41 -> 1
A42: Draft products (not published) | B42: 912
A43: Two-thirds of the published catalog is out of stock — those pages dilute filtering, search, and SEO.

Sheet Filter Readiness Map
A1: Filter Readiness Map — the metadata behind every filter
A2: For each target filter: where the data lives, whether it’s standardized, what field Shopify can filter on, and the work to turn it on. Shopify Search & Discovery builds facets from product options, metafields, or tags only.
A4: Target filter | B4: Metadata source | C4: Data present? | D4: Shopper-ready? | E4: Filterable via | F4: On site? | G4: Work to enable | H4: Effort
A5: Availability | B5: Shopify native | C5: Yes | D5: Yes | E5: Native facet | F5: LIVE | G5: Already on — keep | H5: —
A6: Price | B6: Shopify native | C6: Yes | D6: Yes | E6: Native facet | F6: LIVE | G6: Already on — keep | H6: —
A7: Brand | B7: Vendor field (638 brands) | C7: Yes — 0 missing | D7: No — supplier codes | E7: Vendor facet | F7: OFF | G7: Normalize vendor names (e.g. LEEGIN LEATHER → Brighton), then enable the Brand filter | H7: Low–Med
A8: Garment type | B8: productType codes | C8: Yes | D8: No — cryptic 3-letter codes | E8: Product-type facet | F8: OFF | G8: Map product-type codes to shopper-facing labels, then enable the Product-type filter | H8: Low
A9: Color (text) | B9: Color option | C9: 5,353 of 11,693 | D9: No — 6 spellings | E9: Option facet | F9: OFF | G9: Unify Color/COLOR/colors spellings; add a Color option where missing; enable Color filter | H9: Med
A10: Color (swatches) | B10: shopify.color-pattern metafield | C10: 1,201 (10%) | D10: No — 10% mapped | E10: Metafield facet | F10: OFF | G10: Map ~3,620 raw values → palette metafield; turn on swatches | H10: Med–High
A11: Size | B11: Size option | C11: Apparel mostly yes | D11: No — Size/SIZE split | E11: Option facet | F11: OFF | G11: Unify naming; add Size to 152 apparel/footwear gaps; enable Size filter | H11: Low–Med
A12: Material / fabric | B12: Description text only | C12: ~2,392 mention fabric; 0 structured | D12: No | E12: Metafield (to build) | F12: OFF | G12: Extract fabric words from descriptions → a Material metafield/tag, then enable | H12: High
A13: Occasion / style / fit | B13: None yet | C13: No | D13: No | E13: Tags/metafields (to build) | F13: OFF | G13: Net-new attribute tagging — longest-horizon; what the biggest sites offer | H13: High (future)

Sheet By Garment Type
A1: Filter Readiness by Garment Type (in-stock)
A2: Decoded product types. Color % = Has Color ÷ In Stock; Color gap = In Stock − Has Color where the option applies (blank where it does not, e.g. Size for jewelry). Every % and gap is a live Excel formula over the count columns.
A4: Garment Type | B4: Code | C4: In Stock | D4: Has Color | E4: Color % | F4: Has Size | G4: Size % | H4: Color filter? | I4: Size filter? | J4: Color gap | K4: Size gap | L4: Active (all) | M4: Note
A5: Jewelry | B5: J E W | C5: 3980 | D5: 1047 | E5: =IF(C5=0,0,D5/C5) -> 0.26306533 | F5: 118 | G5: =IF(C5=0,0,F5/C5) -> 0.029648241 | H5: Yes | I5: — | J5: =IF(H5="Yes",C5-D5,"") -> 2933 | K5: =IF(I5="Yes",C5-F5,"") | L5: 12866 | M5: High-volume Color gap
A6: Home & Decor | B6: H O A | C6: 1630 | D6: 300 | E6: =IF(C6=0,0,D6/C6) -> 0.18404908 | F6: 48 | G6: =IF(C6=0,0,F6/C6) -> 0.029447853 | H6: — | I6: — | J6: =IF(H6="Yes",C6-D6,"") | K6: =IF(I6="Yes",C6-F6,"") | L6: 3944
A7: Accessories (general) | B7: A C C | C7: 720 | D7: 298 | E7: =IF(C7=0,0,D7/C7) -> 0.41388889 | F7: 33 | G7: =IF(C7=0,0,F7/C7) -> 0.045833333 | H7: Yes | I7: — | J7: =IF(H7="Yes",C7-D7,"") -> 422 | K7: =IF(I7="Yes",C7-F7,"") | L7: 1911 | M7: High-volume Color gap
A8: Bags & Handbags | B8: B A G | C8: 639 | D8: 475 | E8: =IF(C8=0,0,D8/C8) -> 0.74334898 | F8: 1 | G8: =IF(C8=0,0,F8/C8) -> 0.0015649452 | H8: Yes | I8: — | J8: =IF(H8="Yes",C8-D8,"") -> 164 | K8: =IF(I8="Yes",C8-F8,"") | L8: 2281
A9: Tops | B9: T O C | C9: 435 | D9: 416 | E9: =IF(C9=0,0,D9/C9) -> 0.95632184 | F9: 420 | G9: =IF(C9=0,0,F9/C9) -> 0.96551724 | H9: Yes | I9: Yes | J9: =IF(H9="Yes",C9-D9,"") -> 19 | K9: =IF(I9="Yes",C9-F9,"") -> 15 | L9: 2048 | M9: Size gaps to fill
A10: Special-Occasion Dresses | B10: S O M | C10: 431 | D10: 426 | E10: =IF(C10=0,0,D10/C10) -> 0.98839907 | F10: 426 | G10: =IF(C10=0,0,F10/C10) -> 0.98839907 | H10: Yes | I10: Yes | J10: =IF(H10="Yes",C10-D10,"") -> 5 | K10: =IF(I10="Yes",C10-F10,"") -> 5 | L10: 939
A11: Charms (Brighton) | B11: C H A | C11: 374 | D11: 60 | E11: =IF(C11=0,0,D11/C11) -> 0.16042781 | F11: 5 | G11: =IF(C11=0,0,F11/C11) -> 0.013368984 | H11: — | I11: — | J11: =IF(H11="Yes",C11-D11,"") | K11: =IF(I11="Yes",C11-F11,"") | L11: 891
A12: Baby & Gifts | B12: B A B | C12: 272 | D12: 54 | E12: =IF(C12=0,0,D12/C12) -> 0.19852941 | F12: 20 | G12: =IF(C12=0,0,F12/C12) -> 0.073529412 | H12: — | I12: — | J12: =IF(H12="Yes",C12-D12,"") | K12: =IF(I12="Yes",C12-F12,"") | L12: 782
A13: Jackets & Cardigans | B13: J A K | C13: 244 | D13: 226 | E13: =IF(C13=0,0,D13/C13) -> 0.92622951 | F13: 239 | G13: =IF(C13=0,0,F13/C13) -> 0.9795082 | H13: Yes | I13: Yes | J13: =IF(H13="Yes",C13-D13,"") -> 18 | K13: =IF(I13="Yes",C13-F13,"") -> 5 | L13: 1279
A14: Shoes | B14: S H O | C14: 217 | D14: 183 | E14: =IF(C14=0,0,D14/C14) -> 0.84331797 | F14: 194 | G14: =IF(C14=0,0,F14/C14) -> 0.89400922 | H14: Yes | I14: Yes | J14: =IF(H14="Yes",C14-D14,"") -> 34 | K14: =IF(I14="Yes",C14-F14,"") -> 23 | L14: 456 | M14: Size gaps to fill
A15: Occasion Dresses | B15: S O C | C15: 216 | D15: 211 | E15: =IF(C15=0,0,D15/C15) -> 0.97685185 | F15: 214 | G15: =IF(C15=0,0,F15/C15) -> 0.99074074 | H15: Yes | I15: Yes | J15: =IF(H15="Yes",C15-D15,"") -> 5 | K15: =IF(I15="Yes",C15-F15,"") -> 2 | L15: 473
A16: Christmas / Home | B16: C H H | C16: 198 | D16: 34 | E16: =IF(C16=0,0,D16/C16) -> 0.17171717 | F16: 16 | G16: =IF(C16=0,0,F16/C16) -> 0.080808081 | H16: — | I16: — | J16: =IF(H16="Yes",C16-D16,"") | K16: =IF(I16="Yes",C16-F16,"") | L16: 707
A17: Pants | B17: P A M | C17: 173 | D17: 172 | E17: =IF(C17=0,0,D17/C17) -> 0.99421965 | F17: 167 | G17: =IF(C17=0,0,F17/C17) -> 0.96531792 | H17: Yes | I17: Yes | J17: =IF(H17="Yes",C17-D17,"") -> 1 | K17: =IF(I17="Yes",C17-F17,"") -> 6 | L17: 490
A18: Novelty / Misc | B18: S O X | C18: 166 | D18: 62 | E18: =IF(C18=0,0,D18/C18) -> 0.37349398 | F18: 23 | G18: =IF(C18=0,0,F18/C18) -> 0.13855422 | H18: Yes | I18: — | J18: =IF(H18="Yes",C18-D18,"") -> 104 | K18: =IF(I18="Yes",C18-F18,"") | L18: 506
A19: Dresses | B19: D R C | C19: 164 | D19: 153 | E19: =IF(C19=0,0,D19/C19) -> 0.93292683 | F19: 157 | G19: =IF(C19=0,0,F19/C19) -> 0.95731707 | H19: Yes | I19: Yes | J19: =IF(H19="Yes",C19-D19,"") -> 11 | K19: =IF(I19="Yes",C19-F19,"") -> 7 | L19: 624
A20: Scarves & Wraps | B20: A C S | C20: 145 | D20: 120 | E20: =IF(C20=0,0,D20/C20) -> 0.82758621 | F20: 0 | G20: =IF(C20=0,0,F20/C20) -> 0 | H20: Yes | I20: — | J20: =IF(H20="Yes",C20-D20,"") -> 25 | K20: =IF(I20="Yes",C20-F20,"") | L20: 448
A21: Hair Accessories | B21: A C H | C21: 134 | D21: 33 | E21: =IF(C21=0,0,D21/C21) -> 0.24626866 | F21: 1 | G21: =IF(C21=0,0,F21/C21) -> 0.0074626866 | H21: Yes | I21: — | J21: =IF(H21="Yes",C21-D21,"") -> 101 | K21: =IF(I21="Yes",C21-F21,"") | L21: 224
A22: Reading Glasses | B22: R D R | C22: 122 | D22: 57 | E22: =IF(C22=0,0,D22/C22) -> 0.46721311 | F22: 80 | G22: =IF(C22=0,0,F22/C22) -> 0.6557377 | H22: Yes | I22: Yes | J22: =IF(H22="Yes",C22-D22,"") -> 65 | K22: =IF(I22="Yes",C22-F22,"") -> 42 | L22: 229 | M22: Size gaps to fill
A23: Sunglasses | B23: S U N | C23: 111 | D23: 54 | E23: =IF(C23=0,0,D23/C23) -> 0.48648649 | F23: 1 | G23: =IF(C23=0,0,F23/C23) -> 0.009009009 | H23: Yes | I23: — | J23: =IF(H23="Yes",C23-D23,"") -> 57 | K23: =IF(I23="Yes",C23-F23,"") | L23: 206
A24: Blouses | B24: T O B | C24: 106 | D24: 106 | E24: =IF(C24=0,0,D24/C24) -> 1 | F24: 102 | G24: =IF(C24=0,0,F24/C24) -> 0.96226415 | H24: Yes | I24: Yes | J24: =IF(H24="Yes",C24-D24,"") -> 0 | K24: =IF(I24="Yes",C24-F24,"") -> 4 | L24: 314
A25: Knitwear | B25: K N W | C25: 100 | D25: 92 | E25: =IF(C25=0,0,D25/C25) -> 0.92 | F25: 92 | G25: =IF(C25=0,0,F25/C25) -> 0.92 | H25: Yes | I25: Yes | J25: =IF(H25="Yes",C25-D25,"") -> 8 | K25: =IF(I25="Yes",C25-F25,"") -> 8 | L25: 468
A26: Wallets & SLG | B26: W A L | C26: 99 | D26: 36 | E26: =IF(C26=0,0,D26/C26) -> 0.36363636 | F26: 0 | G26: =IF(C26=0,0,F26/C26) -> 0 | H26: Yes | I26: — | J26: =IF(H26="Yes",C26-D26,"") -> 63 | K26: =IF(I26="Yes",C26-F26,"") | L26: 401
A27: Jeans | B27: P A J | C27: 85 | D27: 75 | E27: =IF(C27=0,0,D27/C27) -> 0.88235294 | F27: 84 | G27: =IF(C27=0,0,F27/C27) -> 0.98823529 | H27: Yes | I27: Yes | J27: =IF(H27="Yes",C27-D27,"") -> 10 | K27: =IF(I27="Yes",C27-F27,"") -> 1 | L27: 256
A28: Hats & Headbands | B28: H A T | C28: 75 | D28: 52 | E28: =IF(C28=0,0,D28/C28) -> 0.69333333 | F28: 0 | G28: =IF(C28=0,0,F28/C28) -> 0 | H28: Yes | I28: — | J28: =IF(H28="Yes",C28-D28,"") -> 23 | K28: =IF(I28="Yes",C28-F28,"") | L28: 407
A29: Sleep & Lounge | B29: S L P | C29: 72 | D29: 23 | E29: =IF(C29=0,0,D29/C29) -> 0.31944444 | F29: 72 | G29: =IF(C29=0,0,F29/C29) -> 1 | H29: Yes | I29: Yes | J29: =IF(H29="Yes",C29-D29,"") -> 49 | K29: =IF(I29="Yes",C29-F29,"") -> 0 | L29: 211
A30: Dresses | B30: D R E | C30: 55 | D30: 53 | E30: =IF(C30=0,0,D30/C30) -> 0.96363636 | F30: 54 | G30: =IF(C30=0,0,F30/C30) -> 0.98181818 | H30: Yes | I30: Yes | J30: =IF(H30="Yes",C30-D30,"") -> 2 | K30: =IF(I30="Yes",C30-F30,"") -> 1 | L30: 265
A31: Tanks | B31: T A N | C31: 52 | D31: 52 | E31: =IF(C31=0,0,D31/C31) -> 1 | F31: 47 | G31: =IF(C31=0,0,F31/C31) -> 0.90384615 | H31: Yes | I31: Yes | J31: =IF(H31="Yes",C31-D31,"") -> 0 | K31: =IF(I31="Yes",C31-F31,"") -> 5 | L31: 155
A32: (none) | B32: (none) | C32: 51 | D32: 29 | E32: =IF(C32=0,0,D32/C32) -> 0.56862745 | F32: 12 | G32: =IF(C32=0,0,F32/C32) -> 0.23529412 | H32: Yes | I32: — | J32: =IF(H32="Yes",C32-D32,"") -> 22 | K32: =IF(I32="Yes",C32-F32,"") | L32: 166
A33: Food & Pantry | B33: F O D | C33: 48 | D33: 2 | E33: =IF(C33=0,0,D33/C33) -> 0.041666667 | F33: 0 | G33: =IF(C33=0,0,F33/C33) -> 0 | H33: — | I33: — | J33: =IF(H33="Yes",C33-D33,"") | K33: =IF(I33="Yes",C33-F33,"") | L33: 64
A34: Tops | B34: T O P | C34: 47 | D34: 47 | E34: =IF(C34=0,0,D34/C34) -> 1 | F34: 46 | G34: =IF(C34=0,0,F34/C34) -> 0.9787234 | H34: Yes | I34: Yes | J34: =IF(H34="Yes",C34-D34,"") -> 0 | K34: =IF(I34="Yes",C34-F34,"") -> 1 | L34: 263
... A81: THK | B81: THK | C81: 1 | D81: 1 | E81: =IF(C81=0,0,D81/C81) -> 1 | F81: 1 | G81: =IF(C81=0,0,F81/C81) -> 1 | H81: Yes | I81: Yes | J81: =IF(H81="Yes",C81-D81,"") -> 0 | K81: =IF(I81="Yes",C81-F81,"") -> 0 | L81: 1

Sheet Problem Worklist
A1: Product Worklist — in-stock products needing a Color or Size option
A2: 4,304 products. Priority 1 = apparel & footwear missing Size (95); 2 = apparel missing Color (161); 3 = accessories missing Color; 4 = jewelry missing Color. Use the column filters to work one batch at a time.
A4: Priority | B4: Product | C4: Garment Type | D4: Brand | E4: Missing Color | F4: Missing Size | G4: Fix (Shopify admin)
A5: 1 | B5: MADE IN ITALY 22383FL FLORAL PRINT SILK BLOUSE | C5: Blouses | D5: LOOK MODE/MX CALIFORNIA | F5: Yes | G5: Edit in Shopify ↗
A6: 1 | B6: MADE IN ITALY 7301 SILK RUFFLE HEM BLOUSE | C6: Blouses | D6: LOOK MODE/MX CALIFORNIA | F6: Yes | G6: Edit in Shopify ↗
A7: 1 | B7: N2DQ6 FLORAL PRINT BLOUSE OS | C7: Blouses | D7: ANGIE/STAR OF INDIA | F7: Yes | G7: Edit in Shopify ↗
A8: 1 | B8: N2DQ7 ABSTRACT PRINT BLOUSE OS | C8: Blouses | D8: ANGIE/STAR OF INDIA | F8: Yes | G8: Edit in Shopify ↗
A9: 1 | B9: INDIA BOUTIQUE 12758 V-NECK DRESS ONE SIZE | C9: Dresses | D9: INDIA BOUTIQUE | F9: Yes | G9: Edit in Shopify ↗
A10: 1 | B10: INDIA BOUTIQUE 13140 OS LUREX PAISLEY DRESS W/ BRAIDED NECK | C10: Dresses | D10: INDIA BOUTIQUE | F10: Yes | G10: Edit in Shopify ↗
A11: 1 | B11: INDIA BOUTIQUE 89509 BIG BUTTON TUNIC | C11: Dresses | D11: K N T | F11: Yes | G11: Edit in Shopify ↗
A12: 1 | B12: MADE IN ITALY 10598 PAISLEY DRESS W/POCKETS | C12: Dresses | D12: URBAN MANGOZ | F12: Yes | G12: Edit in Shopify ↗
A13: 1 | B13: MADE IN ITALY 2078 LONG SLEEVE RUFFLE DRESS ONE SIZE | C13: Dresses | D13: LOOK MODE/MX CALIFORNIA | F13: Yes | G13: Edit in Shopify ↗
A14: 1 | B14: MADE IN ITALY 99995F VINATGE FLORAL MIDI DRESS | C14: Dresses | D14: URBAN MANGOZ | F14: Yes | G14: Edit in Shopify ↗
A15: 1 | B15: MADE IN ITALY CS1421-4 LINEN SHORT SLEEVE DRESS WITH SLITS | C15: Dresses | D15: URBAN MANGOZ | F15: Yes | G15: Edit in Shopify ↗
A16: 1 | B16: Made in Italy 10727 Cheetah Print Dress | C16: Dresses | D16: LOOK MODE/MX CALIFORNIA | F16: Yes | G16: Edit in Shopify ↗
... A18: 1 | B18: COMFYLUX JP5234 FLORAL COVER UP W/TASSELS | C18: Jackets & Cardigans | D18: JASMINE TRADING CORP | F18: Yes | G18: Edit in Shopify ↗
A19: 1 | B19: FLORAL KIMONO KP8862 ONE SIZE | C19: Jackets & Cardigans | D19: Gena Accessories, Inc. | E19: Yes | F19: Yes | G19: Edit in Shopify ↗
A20: 1 | B20: JC0709 PRINT KIMONO | C20: Jackets & Cardigans | D20: JC SUNNY | F20: Yes | G20: Edit in Shopify ↗
A21: 1 | B21: KIMONO-02 REVERSIBLE SILK PATCH KIMINO-SHORT | C21: Jackets & Cardigans | D21: K & K TABLETOPS | F21: Yes | G21: Edit in Shopify ↗
A22: 1 | B22: JUDY BLUE 88861 STRAIGHT TUMMY CONTROL CLASSIC | C22: Jeans | D22: JUDY BLUE | F22: Yes | G22: Edit in Shopify ↗
A23: 1 | B23: GPK-4337BK LACE KIMONO | C23: Knit Cardigans | D23: Gena Accessories, Inc. | F23: Yes | G23: Edit in Shopify ↗
A24: 1 | B24: ORIGINAL FT84201 USA FLAG PRINT KIMONO | C24: Knit Cardigans | D24: ORIGINAL | F24: Yes | G24: Edit in Shopify ↗
A25: 1 | B25: MADE IN ITALY BRIGHT BUTTERFLY SWEATER | C25: Knitwear | D25: YOLLY | E25: Yes | F25: Yes | G25: Edit in Shopify ↗
A26: 1 | B26: MADE IN ITALY FLOWER TREE SWEATER | C26: Knitwear | D26: YOLLY | E26: Yes | F26: Yes | G26: Edit in Shopify ↗
A27: 1 | B27: MADE IN ITALY LL243 V-NECK SWEATER OS | C27: Knitwear | D27: YOLLY | F27: Yes | G27: Edit in Shopify ↗
A28: 1 | B28: MADE IN ITALY MARBLED BLUE/RED SWEATER | C28: Knitwear | D28: YOLLY | E28: Yes | F28: Yes | G28: Edit in Shopify ↗
A29: 1 | B29: MADE IN ITALY ONE SIZE PRINT DOLMAN SLEEVE SWEATER | C29: Knitwear | D29: YOLLY | E29: Yes | F29: Yes | G29: Edit in Shopify ↗
A30: 1 | B30: MADE IN ITALY ONE SIZE PRINTED DOLEMAN SWEATER | C30: Knitwear | D30: YOLLY | E30: Yes | F30: Yes | G30: Edit in Shopify ↗
A31: 1 | B31: PA-4271 SOLID ONE SIZE CROCHET SCALLOPED PONCHO | C31: Knitwear | D31: Gena Accessories, Inc. | F31: Yes | G31: Edit in Shopify ↗
A32: 1 | B32: SELENE. L SHW2426 TIED SWEATER | C32: Knitwear | D32: MAX ACCESSORIES INC | F32: Yes | G32: Edit in Shopify ↗
A33: 1 | B33: LG-809 LG-810 FLEECE LINED LEGGING W/STONES | C33: Leggings | D33: AZZ/QZZ TRADING INC | E33: Yes | F33: Yes | G33: Edit in Shopify ↗
A34: 1 | B34: LG801 LG806 PRINT LINED LEGGING | C34: Leggings | D34: AZZ/QZZ TRADING INC | E34: Yes | F34: Yes | G34: Edit in Shopify ↗
A35: 1 | B35: ONE SIZE SPARKLING STONE TRIMMED LEGGINGS P-2655 | C35: Leggings | D35: GM FASHION USA INC | E35: Yes | F35: Yes | G35: Edit in Shopify ↗
A36: 1 | B36: MESH & STONE SHORT TIE FRONT CARDIGAN | C36: Occasion Dresses | D36: BORUN AMERICA JEWELRY | E36: Yes | F36: Yes | G36: Edit in Shopify ↗
A37: 1 | B37: MONTAGE EW118052*** VELVET FLOCKED EMPIRE | C37: Occasion Dresses | D37: JBR | F37: Yes | G37: Edit in Shopify ↗
A38: 1 | B38: J04A COMFORT CONTROL DENIM LEGGING OS | C38: Pants | D38: SUPERLINE | F38: Yes | G38: Edit in Shopify ↗
A39: 1 | B39: MADE IN ITALY 13964 FISHNET TRIM LINEN PANT | C39: Pants | D39: URBAN MANGOZ | F39: Yes | G39: Edit in Shopify ↗
A40: 1 | B40: MADE IN ITALY 21541 FLORAL PRINT PANT | C40: Pants | D40: URBAN MANGOZ | F40: Yes | G40: Edit in Shopify ↗
A41: 1 | B41: MADE IN ITALY LL1318 STRETCHWAIST SOLID JOGGER PANT OS | C41: Pants | D41: YOLLY | F41: Yes | G41: Edit in Shopify ↗
A42: 1 | B42: MADE IN ITALY LU3071 SUEDE JOGGER PANT OS | C42: Pants | D42: YOLLY | F42: Yes | G42: Edit in Shopify ↗
...

Sheet Color Values
A1: Color Values — In-Stock Products
A2: 3,620 unique color values across 5,353 in-stock products with a Color option (6,044 unique across full active catalog). Value sprawl is why a clean palette metafield is needed.
A3: In-stock products with a Color option (scope for %): | C3: 5353
A4: Rank | B4: Color Value | C4: In-Stock Products | D4: % of in-stock color products
A5: 1 | B5: Black | C5: 1203 | D5: =C5/$C$3 -> 0.22473379
A6: 2 | B6: Navy | C6: 477 | D6: =C6/$C$3 -> 0.089108911
A7: 3 | B7: Silver | C7: 459 | D7: =C7/$C$3 -> 0.08574631
A8: 4 | B8: White | C8: 435 | D8: =C8/$C$3 -> 0.081262843
A9: 5 | B9: Blue | C9: 339 | D9: =C9/$C$3 -> 0.063328974
A10: 6 | B10: Pink | C10: 338 | D10: =C10/$C$3 -> 0.063142163
A11: 7 | B11: Red | C11: 323 | D11: =C11/$C$3 -> 0.060339996
A12: 8 | B12: Gold | C12: 317 | D12: =C12/$C$3 -> 0.059219129
A13: 9 | B13: Grey | C13: 242 | D13: =C13/$C$3 -> 0.045208294
A14: 10 | B14: Purple | C14: 177 | D14: =C14/$C$3 -> 0.033065571
A15: 11 | B15: Green | C15: 174 | D15: =C15/$C$3 -> 0.032505137
A16: 12 | B16: Beige | C16: 163 | D16: =C16/$C$3 -> 0.030450215
... A64: 60 | B64: Denim Ignite | C64: 25 | D64: =C64/$C$3 -> 0.0046702783

Sheet Size Values
A1: Size Values — In-Stock Products
A2: 348 unique size values across 3,050 in-stock products with a Size option
A4: Rank | B4: Size Value | C4: In-Stock Products | D4: Category
A5: 1 | B5: M | C5: 1297 | D5: Letter
A6: 2 | B6: L | C6: 1294 | D6: Letter
A7: 3 | B7: S | C7: 1249 | D7: Letter
A8: 4 | B8: XL | C8: 1056 | D8: Letter
A9: 5 | B9: 10 | C9: 692 | D9: Numeric
A10: 6 | B10: 8 | C10: 601 | D10: Numeric
A11: 7 | B11: 12 | C11: 503 | D11: Numeric
A12: 8 | B12: 6 | C12: 463 | D12: Numeric
A13: 9 | B13: 14 | C13: 441 | D13: Numeric
A14: 10 | B14: 16 | C14: 322 | D14: Numeric
A15: 11 | B15: 4 | C15: 214 | D15: Numeric
A16: 12 | B16: 9 | C16: 196 | D16: Numeric
... A64: 60 | B64: 2XL | C64: 28 | D64: Other

Sheet Option Types
A1: Complete Inventory of Product Option Types
A2: 36,047 active products scanned | 17,375 have no options at all (“Default Title”). ‘Spellings found’ shows every naming variant that fragments a filter (e.g. Size vs SIZE).
A4: Option (canonical) | B4: Active Products | C4: In Stock | D4: Unique Values | E4: Spellings found | F4: Assessment
A5: Color | B5: 16988 | C5: 5349 | D5: 6038 | E5: Color:12906, COLOR:4051, color:17, COLOR :11, Color :2, color :1 | F5: PRIMARY filter — fix naming, then map values
A6: Size | B6: 10017 | C6: 3050 | D6: 476 | E6: Size:7203, SIZE:2811, SIZE :3 | F6: PRIMARY filter — fix naming
A7: Style | B7: 221 | C7: 107 | D7: 668 | E7: STYLE:117, Style:98, STYLE :5, style :1 | F7: Minor — high value-sprawl
A8: Scent | B8: 27 | C8: 24 | D8: 51 | E8: SCENT:24, Scent:3 | F8: Niche (candles, home)
A9: Shoe Size | B9: 25 | C9: 23 | D9: 17 | E9: Shoe size:25 | F9: Clean — footwear only
A10: Colors | B10: 7 | C10: 4 | D10: 18 | E10: COLORS:7 | F10: BUG — merge into Color
A11: Print | B11: 6 | C11: 3 | D11: 20 | E11: PRINT:4, Print:2 | F11: Niche
A12: Ring Size | B12: 5 | C12: 4 | D12: 4 | E12: Ring size:5 | F12: Niche — jewelry
A13: Strength | B13: 5 | C13: 4 | D13: 15 | E13: STRENGTH:5 | F13: Reading glasses
A14: Animal | B14: 3 | C14: 3 | D14: 15 | E14: ANIMAL:3 | F14: Review — non-standard option
A15: Fragrance | B15: 2 | C15: 1 | D15: 6 | E15: FRAGRANCE:2 | F15: Review — non-standard option
A16: Black | B16: 2 | C16: 0 | D16: 14 | E16: BLACK:2 | F16: Review — non-standard option
... A40: Accessory Size | B40: 1 | C40: 1 | D40: 2 | E40: Accessory size:1 | F40: Review — non-standard option

Sheet Data Quality
A1: Data Quality — Option Naming Cleanup List
A2: 7,059 products carry a misspelled or inconsistent option name. Fixes change only the option LABEL — no variants, prices, or inventory are touched.
A4: Issue | B4: Current Spelling | C4: Should Be | D4: Products Affected
A5: Inconsistent casing | B5: COLOR | C5: Color | D5: 4051
A6: Inconsistent casing | B6: SIZE | C6: Size | D6: 2811
A7: Inconsistent casing | B7: STYLE | C7: Style | D7: 117
A8: Inconsistent casing | B8: SCENT | C8: Scent | D8: 24
A9: Inconsistent casing | B9: color | C9: Color | D9: 17
A10: Trailing/leading space | B10: COLOR | C10: Color | D10: 11
A11: Inconsistent casing | B11: COLORS | C11: Color | D11: 7
A12: Trailing/leading space | B12: STYLE | C12: Style | D12: 5
A13: Inconsistent casing | B13: STRENGTH | C13: Strength | D13: 5
A14: Inconsistent casing | B14: PRINT | C14: Print | D14: 4
A15: Trailing/leading space | B15: SIZE | C15: Size | D15: 3
A16: Trailing/leading space | B16: Color | C16: Color | D16: 2
... A18: Trailing/leading space | B18: style | C18: Style | D18: 1
A19: TOTAL (rename in one scripted batch) | D19: =SUM(D5:D18) -> 7059
A21: NON-STANDARD OPTION NAMES — typos & values used as options
A22: Verdict | B22: Option Name | D22: Products
A23: Value used as option name | B23: ANIMAL | D23: 3
A24: Non-standard — review | B24: FRAGRANCE | D24: 2
A25: Value used as option name | B25: BLACK | D25: 2
A26: Invalid — not a usable option | B26: Download Our App Now! | D26: 1
A27: Non-standard — review | B27: Bracelet design | D27: 1
A28: Typo — should be Size | B28: Siz | D28: 1
A29: Typo — should be Size | B29: S1ze | D29: 1
A30: Non-standard — review | B30: INITIAL | D30: 1
A31: Non-standard — review | B31: Saying | D31: 1
A32: Non-standard — review | B32: Verse | D32: 1
A33: Non-standard — review | B33: Character | D33: 1
A34: Non-standard — review | B34: MATERIAL | D34: 1
... A49: Non-standard — review | B49: Accessory size | D49: 1

Sheet Color Swatch Metadata
A1: Color Swatch Metadata — the swatch filter’s foundation
A2: Shopify’s shopify.color-pattern metafield maps messy color names to a standard palette. Swatches can’t render without it.
A4: Metric | B4: Value | C4: % of scope
A5: In-stock products with color-pattern metafield | B5: 1201 | C5: =B5/Summary!$B$39 -> 0.10271102
A6: Active products with color-pattern metafield | B6: 1566 | C6: =B6/Summary!$B$41 -> 0.043443282
A7: Unique palette colors referenced (in-stock) | B7: 290
A8: Unique palette colors referenced (active) | B8: 331
A9: Unique raw color values to map (in-stock) | B9: 3620
A11: Read: only 10% of in-stock products have a mapped palette color. The remaining ~3,620 raw values need mapping to ~290 palette colors for clean swatch filtering.

Sheet Material & Brand
A1: Material & Brand — facets that need metadata built
A2: Two high-value filters whose data isn’t yet in a filterable field.
A4: MATERIAL / FABRIC — data is trapped in product descriptions
A5: Metric | B5: Value | C5: % of in-stock
A6: In-stock products mentioning a fabric in the description | B6: 2392 | C6: =B6/Summary!$B$39 -> 0.20456683
A7: In-stock products with a structured Material option/field | B7: 0 | C7: =B7/Summary!$B$39 -> 0
A8: Most-mentioned fabrics: | B8: polyester (1114), cotton (813), spandex (767), leather (331), rayon (297), nylon (275), viscose (144), denim (130)
A10: Fabric is described in prose but not stored as a filterable attribute. A script can extract fabric keywords from descriptions into a Material metafield/tag — turning ~1 in 5 products into material-filterable with no manual tagging.
A13: BRAND — data is complete but values are supplier codes
A14: Metric | B14: Value
A15: Distinct vendor values (in-stock) | B15: 638
A16: In-stock products missing a vendor | B16: 0
A18: Top vendor values (note: supplier names, not shopper brands):
A19: LEEGIN LEATHER | B19: 1691
A20: AST | B20: 622
A21: SRB | B21: 389
A22: PERIWINKLE/BARLOW DESIGNS | B22: 272
A23: E & S PETS | B23: 237
A24: MULTIPLES/SHARON YOUNG | B24: 172
A25: B&G SALES | B25: 145
A26: RACHEL MARIE DESIGNS | B26: 140
A28: The Brand filter is data-complete (0 missing) but the values are supplier/distributor codes (e.g. ‘LEEGIN LEATHER’ = Brighton). Normalize vendor names to shopper-facing brands, then the Brand filter can be switched on immediately.

Sheet Fix Roadmap
A1: Filter Readiness — Fix Roadmap
A2: Sequenced to switch on the most filters per hour of work. Phases 1–3 turn on filters using data that already exists.
A4: Phase | B4: Action | C4: Unlocks filter | D4: Effort | E4: Risk
A5: Phase 1 | B5: Option naming cleanup — unify Color/COLOR/colors and Size/SIZE; fix the typos and invalid option names (see Data Quality). | C5: Color, Size (prereq) | D5: 7,059 labels / 2–3 hrs | E5: Low — labels only; no variants/prices touched
A6: Phase 2 | B6: Enable the filters whose data is already complete — Brand (after vendor-name normalization) and Garment Type (after code→label mapping). | C6: Brand, Garment type | D6: Brand + type / 1–2 days | E6: Low — mapping + Search & Discovery config
A7: Phase 3 | B7: Turn on Color & Size filters in Search & Discovery + activate color swatches on the theme (currently no swatch config). | C7: Color, Size | D7: Theme + app / 2–4 hrs | E7: None — display settings, instantly reversible
A8: Phase 4 | B8: Canonical color mapping — map raw color values to Shopify’s palette (color-pattern metafield) so swatches render. | C8: Color swatches | D8: ~3,620 values / 1–2 wks | E8: Low — additive metadata
A9: Phase 5 | B9: Fill remaining option gaps — add Size to apparel & footwear and Color where the product type uses it (see Product Worklist). | C9: Color, Size coverage | D9: 152 Size + 4,194 Color / incremental | E9: Medium — product edits; dry-run per type
A10: Phase 6 | B10: Build the Material filter — extract fabric from descriptions into a Material metafield/tag, then enable. | C10: Material / fabric | D10: ~2,392 products / 1–2 wks | E10: Low — additive, script-extracted
A11: Phase 7 | B11: Out-of-stock cleanup — archive stale zero-inventory listings (mostly 2018–2022) so filters/search reflect real stock. | C11: All (signal quality) | D11: 24,354 OOS / 1–2 days | E11: Medium — reversible (archive, don’t delete)
A12: Phase 8 | B12: Publish & verify — confirm every enabled filter on key collections, re-crawl, spot-check top 20 collections. | C12: Verification | D12: Site-wide / 2–3 hrs | E12: Low
